<mujoco model="abb_irb1600_6_12_ghost">
    <body name="g4_base" pos="0.0 0.0 0.07847612194" euler="0 0 2.0944">
        <site name="g4_base"/>
        <geom type="mesh"  rgba="0.9 0.9 0.9 0.5" mesh="base_link" contype="0" conaffinity="0"/>
        <body name="g4_link_1" pos="0 0 0">
            <inertial pos="0.0444007 -0.00834001 0.340163" quat="0.575539 0.391509 0.239129 0.676973" mass="44.6131" diaginertia="1.4797 1.22366 0.686463" />
            <joint name="g4_joint_1" pos="0 0 0" axis="0 0 1" type="hinge" limited="true" range="-3.14159 3.14159" />
            <geom type="mesh"  rgba="0.9 0.9 0.9 0.5" mesh="link_1" contype="0" conaffinity="0"/>
            <body name="g4_link_2" pos="0.15 0 0.4865">
                <inertial pos="-0.000162316 -0.181341 0.209041" quat="0.711714 -0.0257675 0.0284926 0.701418" mass="8.36275" diaginertia="0.278683 0.272236 0.0199549" />
                <joint name="g4_joint_2" pos="0 0 0" axis="0 1 0" type="hinge" limited="true" range="-1.0995 1.9198" />
                <geom type="mesh"  rgba="0.9 0.9 0.9 0.5" mesh="link_2"  contype="0" conaffinity="0"/>
                <body name="g4_link_3" pos="0 0 0.475">
                    <inertial pos="0.0211951 0.0175275 -0.0132258" quat="0.25664 0.667078 0.208923 0.667454" mass="16.0317" diaginertia="0.262454 0.244916 0.112849" />
                    <joint name="g4_joint_3" pos="0 0 0" axis="0 1 0" type="hinge" limited="true" range="-4.1015 0.9599" />
                    <geom type="mesh"  rgba="0.9 0.9 0.9 0.5" mesh="link_3" contype="0" conaffinity="0"/>
                    <body name="g4_link_4" pos="0.3 0 0">
                        <inertial pos="0.184489 -0.000718245 -1.22946e-05" quat="0.0065586 0.706564 -0.00374281 0.707609" mass="2.96489" diaginertia="0.0275833 0.0267565 0.00469567" />
                        <joint name="g4_joint_4" pos="0 0 0" axis="1 0 0" type="hinge" limited="true" range="-3.4906 3.4906" />
                        <geom type="mesh"  rgba="0.9 0.9 0.9 0.5" mesh="link_4" contype="0" conaffinity="0"/>
                        <body name="g4_link_5" pos="0.3 0 0">
                            <inertial pos="1.38541e-08 2.00457e-06 5.41082e-08" quat="0.707107 5.68027e-06 5.68027e-06 0.707107" mass="0.183296" diaginertia="0.000132901 9.60035e-05 9.12007e-05" />
                            <joint name="g4_joint_5" pos="0 0 0" axis="0 1 0" type="hinge" limited="true" range="-2.0071 2.0071" />
                            <geom type="mesh"  rgba="0.9 0.9 0.9 0.5" mesh="link_5" contype="0" conaffinity="0"/>
                            <body name="g4_link_6" pos="0.065 0 0">
                                <site name="g4_ee"/>
                                <inertial pos="-0.0164152 2.0728e-06 0.000267316" quat="0.502798 0.497187 0.497346 0.50264" mass="0.0748395" diaginertia="3.09311e-05 3.06155e-05 1.53407e-05" />
                                <joint name="g4_joint_6" pos="0 0 0" axis="1 0 0" type="hinge" limited="true" range="-6.9813 6.9813" />
                                <geom type="mesh"  rgba="0.9 0.9 0.9 0.5" mesh="link_6" contype="0" conaffinity="0"/>
                                <geom name="g4_shield" type="box" rgba=".9 0 0 0.5" pos="0.005 0 0" size="0.005 0.15 0.15" contype="10" conaffinity="21" />
                            </body>
                        </body>
                    </body>
                </body>
            </body>
        </body>            
    </body>
</mujoco>
